<robot name="3dof_cartesian_robot">
  <link name="base_link">
    <inertial>
      <mass value="1.0"/>
      <inertia ixx="0.1" ixy="0.0" ixz="0.0" iyy="0.1" iyz="0.0" izz="0.1"/>
    </inertial>
  </link>
  <link name="link_x">
    <inertial>
      <mass value="0.5"/>
      <inertia ixx="0.05" ixy="0.0" ixz="0.0" iyy="0.05" iyz="0.0" izz="0.05"/>
    </inertial>
  </link>
  <link name="link_y">
    <inertial>
      <mass value="0.5"/>
      <inertia ixx="0.05" ixy="0.0" ixz="0.0" iyy="0.05" iyz="0.0" izz="0.05"/>
    </inertial>
  </link>
  <link name="link_z">
    <inertial>
      <mass value="0.5"/>
      <inertia ixx="0.05" ixy="0.0" ixz="0.0" iyy="0.05" iyz="0.0" izz="0.05"/>
    </inertial>
  </link>

  <joint name="joint_x" type="prismatic">
    <parent link="base_link"/>
    <child link="link_x"/>
    <axis xyz="1 0 0"/>
    <limit lower="0" upper="1" effort="100" velocity="0.5"/>
  </joint>

  <joint name="joint_y" type="prismatic">
    <parent link="link_x"/>
    <child link="link_y"/>
    <axis xyz="0 1 0"/>
    <limit lower="0" upper="1" effort="100" velocity="0.5"/>
  </joint>

  <joint name="joint_z" type="prismatic">
    <parent link="link_y"/>
    <child link="link_z"/>
    <axis xyz="0 0 1"/>
    <limit lower="0" upper="1" effort="100" velocity="0.5"/>
  </joint>
</robot>
